---
title: 异常处理 (try, catch, throw) 教程
date: 2023-10-05
description: 本课程详细讲解如何在编程中使用try, catch, throw进行异常处理，确保代码的健壮性和可维护性。
slug: exception-handling-try-catch-throw
tags:
  - 异常处理
  - 编程基础
  - 错误处理
category: 编程基础
keywords:
  - try catch
  - 异常处理
  - throw
---

# 异常处理 (try, catch, throw)

## 概述

在编程中，异常处理是一种重要的机制，用于处理程序运行时可能出现的错误或异常情况。JavaScript 提供了 `try`, `catch`, 和 `throw` 语句来帮助开发者捕获和处理这些异常。通过合理使用异常处理，我们可以提高代码的健壮性，确保程序在遇到错误时能够优雅地处理，而不是崩溃。

## 理论解释

### 1. `try` 语句

`try` 语句用于包裹可能会抛出异常的代码块。如果 `try` 块中的代码执行过程中抛出了异常，程序将立即跳转到 `catch` 块。

### 2. `catch` 语句

`catch` 语句紧跟在 `try` 语句之后，用于捕获并处理 `try` 块中抛出的异常。`catch` 块中可以访问一个参数，通常命名为 `error` 或 `err`，它包含了异常的详细信息。

### 3. `throw` 语句

`throw` 语句用于手动抛出一个异常。你可以抛出任何类型的值，但通常抛出一个 `Error` 对象，因为它包含了错误信息和堆栈跟踪，便于调试。

### 4. `finally` 语句

`finally` 语句是可选的，它紧跟在 `catch` 语句之后。无论是否抛出异常，`finally` 块中的代码都会执行。通常用于清理资源或执行一些必须完成的操作。

## 代码示例

### 基本异常处理

```javascript
try {
    // 可能会抛出异常的代码
    let result = 10 / 0; // 这里会抛出一个异常
    console.log(result); // 这行代码不会执行
} catch (error) {
    // 捕获并处理异常
    console.error("捕获到异常:", error.message);
}
```

### 手动抛出异常

```javascript
function divide(a, b) {
    if (b === 0) {
        throw new Error("除数不能为零");
    }
    return a / b;
}

try {
    let result = divide(10, 0);
    console.log(result);
} catch (error) {
    console.error("捕获到异常:", error.message);
}
```

### 使用 `finally`

```javascript
try {
    let result = 10 / 0;
    console.log(result);
} catch (error) {
    console.error("捕获到异常:", error.message);
} finally {
    console.log("无论是否抛出异常，这行代码都会执行");
}
```

## 实践练习

### 练习 1: 处理文件读取异常

假设你正在编写一个读取文件内容的函数。文件可能不存在或无法读取，因此你需要使用异常处理来确保程序不会崩溃。

```javascript
function readFile(filePath) {
    try {
        let content = require('fs').readFileSync(filePath, 'utf8');
        console.log("文件内容:", content);
    } catch (error) {
        console.error("读取文件时发生错误:", error.message);
    }
}

readFile("nonexistent-file.txt");
```

### 练习 2: 自定义异常类型

创建一个自定义异常类型，并在函数中使用它。

```javascript
class CustomError extends Error {
    constructor(message) {
        super(message);
        this.name = "CustomError";
    }
}

function validateAge(age) {
    if (age < 0) {
        throw new CustomError("年龄不能为负数");
    }
    console.log("年龄验证通过");
}

try {
    validateAge(-5);
} catch (error) {
    console.error("捕获到自定义异常:", error.message);
}
```

## 总结

异常处理是编程中不可或缺的一部分，它帮助我们在程序运行时捕获和处理错误，确保程序的稳定性和可靠性。通过 `try`, `catch`, `throw` 和 `finally` 语句，我们可以有效地管理异常，使代码更加健壮。

希望这篇教程能帮助你理解并掌握 JavaScript 中的异常处理机制。继续练习和实践，你将能够编写出更加稳定和可靠的代码。