---
title: 深入理解Python中的错误处理
date: 2023-10-05
description: 本课程将深入探讨Python中的错误处理机制，包括异常捕获、自定义异常以及如何优雅地处理程序中的错误。
slug: python-error-handling
tags:
  - Python
  - 错误处理
  - 编程基础
category: 编程教程
keywords:
  - Python异常
  - 错误处理
  - try-except
---

# 错误处理

在编程中，错误处理是一个至关重要的主题。它确保了程序在遇到意外情况时能够优雅地处理问题，而不是崩溃或产生不可预测的行为。Rust 提供了一套强大的错误处理机制，使得开发者能够清晰地表达和处理错误。

## 1. Rust 中的错误类型

在 Rust 中，错误通常分为两大类：可恢复错误（Recoverable Errors）和不可恢复错误（Unrecoverable Errors）。

### 1.1 可恢复错误

可恢复错误通常表示程序可以继续执行的情况。Rust 使用 `Result<T, E>` 枚举来处理这类错误。`Result` 枚举有两个变体：

- `Ok(T)`: 表示操作成功，并返回一个值 `T`。
- `Err(E)`: 表示操作失败，并返回一个错误类型 `E`。

```rust
enum Result<T, E> {
    Ok(T),
    Err(E),
}
```

### 1.2 不可恢复错误

不可恢复错误通常表示程序无法继续执行的情况。Rust 使用 `panic!` 宏来处理这类错误。当 `panic!` 被调用时，程序会立即终止并打印错误信息。

```rust
fn main() {
    panic!("Something went wrong!");
}
```

## 2. 处理可恢复错误

### 2.1 使用 `Result` 枚举

让我们通过一个简单的例子来理解如何使用 `Result` 枚举。假设我们有一个函数 `divide`，它接受两个整数并返回它们的商。如果除数为零，函数应该返回一个错误。

```rust
fn divide(a: i32, b: i32) -> Result<i32, String> {
    if b == 0 {
        return Err("Division by zero is not allowed".to_string());
    }
    Ok(a / b)
}

fn main() {
    let result = divide(10, 2);
    match result {
        Ok(value) => println!("Result: {}", value),
        Err(e) => println!("Error: {}", e),
    }
}
```

在这个例子中，`divide` 函数返回一个 `Result<i32, String>`。如果除数 `b` 为零，函数返回一个 `Err` 变体，否则返回 `Ok` 变体。

### 2.2 使用 `?` 运算符

Rust 提供了一个方便的 `?` 运算符来简化错误处理。`?` 运算符可以用于 `Result` 类型的值，如果值是 `Err`，它会立即返回错误；如果值是 `Ok`，它会提取内部的值。

```rust
fn divide(a: i32, b: i32) -> Result<i32, String> {
    if b == 0 {
        return Err("Division by zero is not allowed".to_string());
    }
    Ok(a / b)
}

fn main() -> Result<(), String> {
    let result = divide(10, 2)?;
    println!("Result: {}", result);
    Ok(())
}
```

在这个例子中，`?` 运算符用于 `divide(10, 2)` 的结果。如果 `divide` 返回 `Err`，`main` 函数会立即返回相同的错误。

## 3. 处理不可恢复错误

### 3.1 使用 `panic!` 宏

如前所述，`panic!` 宏用于处理不可恢复的错误。当程序遇到无法处理的错误时，可以使用 `panic!` 来终止程序并打印错误信息。

```rust
fn main() {
    panic!("Something went wrong!");
}
```

### 3.2 使用 `unwrap` 和 `expect`

在某些情况下，开发者可能希望在遇到错误时立即终止程序。Rust 提供了 `unwrap` 和 `expect` 方法来实现这一点。

- `unwrap`: 如果 `Result` 是 `Ok`，返回内部的值；如果是 `Err`，调用 `panic!`。
- `expect`: 类似于 `unwrap`，但它允许开发者提供一个自定义的错误信息。

```rust
fn main() {
    let result = divide(10, 0).unwrap(); // 如果 divide 返回 Err，程序会 panic
    println!("Result: {}", result);
}
```

```rust
fn main() {
    let result = divide(10, 0).expect("Division by zero is not allowed"); // 自定义错误信息
    println!("Result: {}", result);
}
```

## 4. 实践练习

### 练习 1: 文件读取

编写一个程序，尝试读取一个文件的内容。如果文件不存在或读取失败，程序应该返回一个错误。

```rust
use std::fs::File;
use std::io::Read;

fn read_file(path: &str) -> Result<String, std::io::Error> {
    let mut file = File::open(path)?;
    let mut contents = String::new();
    file.read_to_string(&mut contents)?;
    Ok(contents)
}

fn main() {
    match read_file("example.txt") {
        Ok(contents) => println!("File contents:\n{}", contents),
        Err(e) => println!("Error reading file: {}", e),
    }
}
```

### 练习 2: 自定义错误类型

定义一个自定义错误类型，并在函数中使用它。

```rust
#[derive(Debug)]
enum MyError {
    DivisionByZero,
    OtherError(String),
}

fn divide(a: i32, b: i32) -> Result<i32, MyError> {
    if b == 0 {
        return Err(MyError::DivisionByZero);
    }
    Ok(a / b)
}

fn main() {
    match divide(10, 0) {
        Ok(value) => println!("Result: {}", value),
        Err(e) => println!("Error: {:?}", e),
    }
}
```

## 5. 总结

错误处理是编程中不可或缺的一部分。Rust 通过 `Result` 枚举和 `panic!` 宏提供了强大的错误处理机制。通过理解和实践这些概念，开发者可以编写出更加健壮和可靠的程序。

在接下来的课程中，我们将深入探讨 Rust 的其他高级主题，如智能指针、并发编程和异步 I/O。